Traceback (most recent call last):
  File "/opt/hostedtoolcache/Python/3.10.8/x64/lib/python3.10/site-packages/jupyter_cache/executors/utils.py", line 51, in single_nb_execution
    executenb(
  File "/opt/hostedtoolcache/Python/3.10.8/x64/lib/python3.10/site-packages/nbclient/client.py", line 1204, in execute
    return NotebookClient(nb=nb, resources=resources, km=km, **kwargs).execute()
  File "/opt/hostedtoolcache/Python/3.10.8/x64/lib/python3.10/site-packages/nbclient/util.py", line 84, in wrapped
    return just_run(coro(*args, **kwargs))
  File "/opt/hostedtoolcache/Python/3.10.8/x64/lib/python3.10/site-packages/nbclient/util.py", line 62, in just_run
    return loop.run_until_complete(coro)
  File "/opt/hostedtoolcache/Python/3.10.8/x64/lib/python3.10/asyncio/base_events.py", line 649, in run_until_complete
    return future.result()
  File "/opt/hostedtoolcache/Python/3.10.8/x64/lib/python3.10/site-packages/nbclient/client.py", line 663, in async_execute
    await self.async_execute_cell(
  File "/opt/hostedtoolcache/Python/3.10.8/x64/lib/python3.10/site-packages/nbclient/client.py", line 965, in async_execute_cell
    await self._check_raise_for_error(cell, cell_index, exec_reply)
  File "/opt/hostedtoolcache/Python/3.10.8/x64/lib/python3.10/site-packages/nbclient/client.py", line 862, in _check_raise_for_error
    raise CellExecutionError.from_cell_and_msg(cell, exec_reply_content)
nbclient.exceptions.CellExecutionError: An error occurred while executing the following cell:
------------------
import altair as alt
from vega_datasets import data
import pandas as pd

movies = (
    data.movies()
    .drop(columns=['US_DVD_Sales', 'Director', 'Source', 'Creative_Type'])
    .dropna(subset=['Running_Time_min', 'Major_Genre', 'Rotten_Tomatoes_Rating', 'IMDB_Rating', 'MPAA_Rating'])
    .assign(Release_Year=lambda df: pd.to_datetime(df['Release_Date']).dt.year)
    .reset_index(drop=True))
movies
------------------

[0;31m---------------------------------------------------------------------------[0m
[0;31mModuleNotFoundError[0m                       Traceback (most recent call last)
Cell [0;32mIn[1], line 1[0m
[0;32m----> 1[0m [38;5;28;01mimport[39;00m [38;5;21;01maltair[39;00m [38;5;28;01mas[39;00m [38;5;21;01malt[39;00m
[1;32m      2[0m [38;5;28;01mfrom[39;00m [38;5;21;01mvega_datasets[39;00m [38;5;28;01mimport[39;00m data
[1;32m      3[0m [38;5;28;01mimport[39;00m [38;5;21;01mpandas[39;00m [38;5;28;01mas[39;00m [38;5;21;01mpd[39;00m

[0;31mModuleNotFoundError[0m: No module named 'altair'
ModuleNotFoundError: No module named 'altair'

